<?xml version="1.0" encoding="UTF-8"?>
<!-- Generated by org.testng.reporters.JUnitReportReporter -->
<testsuite hostname="Rohit" failures="0" tests="1" name="practice.datadriventesting.SampleUnitTestCaseToCheckProjectInBackEnd" time="0.473" errors="1" timestamp="2024-07-25T17:55:56 IST" skipped="0">
  <testcase classname="practice.datadriventesting.SampleUnitTestCaseToCheckProjectInBackEnd" name="projectTestTest" time="0.473">
    <error message="Communications link failure

The last packet sent successfully to the server was 0 milliseconds ago. The driver has not received any packets from the server." type="com.mysql.cj.jdbc.exceptions.CommunicationsException">
      <![CDATA[com.mysql.cj.jdbc.exceptions.CommunicationsException: Communications link failure

The last packet sent successfully to the server was 0 milliseconds ago. The driver has not received any packets from the server.
at com.mysql.cj.jdbc.exceptions.SQLError.createCommunicationsException(SQLError.java:165)
at com.mysql.cj.jdbc.exceptions.SQLExceptionsMapping.translateException(SQLExceptionsMapping.java:55)
at com.mysql.cj.jdbc.ConnectionImpl.createNewIO(ConnectionImpl.java:845)
at com.mysql.cj.jdbc.ConnectionImpl.<init>(ConnectionImpl.java:420)
at com.mysql.cj.jdbc.ConnectionImpl.getInstance(ConnectionImpl.java:238)
at com.mysql.cj.jdbc.NonRegisteringDriver.connect(NonRegisteringDriver.java:180)
at java.sql/java.sql.DriverManager.getConnection(DriverManager.java:683)
at java.sql/java.sql.DriverManager.getConnection(DriverManager.java:230)
at practice.datadriventesting.SampleUnitTestCaseToCheckProjectInBackEnd.projectTestTest(SampleUnitTestCaseToCheckProjectInBackEnd.java:28)
at java.base/jdk.internal.reflect.DirectMethodHandleAccessor.invoke(DirectMethodHandleAccessor.java:103)
at java.base/java.lang.reflect.Method.invoke(Method.java:580)
at org.testng.internal.invokers.MethodInvocationHelper.invokeMethod(MethodInvocationHelper.java:139)
at org.testng.internal.invokers.TestInvoker.invokeMethod(TestInvoker.java:677)
at org.testng.internal.invokers.TestInvoker.invokeTestMethod(TestInvoker.java:221)
at org.testng.internal.invokers.MethodRunner.runInSequence(MethodRunner.java:50)
at org.testng.internal.invokers.TestInvoker$MethodInvocationAgent.invoke(TestInvoker.java:969)
at org.testng.internal.invokers.TestInvoker.invokeTestMethods(TestInvoker.java:194)
at org.testng.internal.invokers.TestMethodWorker.invokeTestMethods(TestMethodWorker.java:148)
at org.testng.internal.invokers.TestMethodWorker.run(TestMethodWorker.java:128)
at java.base/java.util.ArrayList.forEach(ArrayList.java:1596)
at org.testng.TestRunner.privateRun(TestRunner.java:829)
at org.testng.TestRunner.run(TestRunner.java:602)
at org.testng.SuiteRunner.runTest(SuiteRunner.java:437)
at org.testng.SuiteRunner.runSequentially(SuiteRunner.java:431)
at org.testng.SuiteRunner.privateRun(SuiteRunner.java:391)
at org.testng.SuiteRunner.run(SuiteRunner.java:330)
at org.testng.SuiteRunnerWorker.runSuite(SuiteRunnerWorker.java:52)
at org.testng.SuiteRunnerWorker.run(SuiteRunnerWorker.java:95)
at org.testng.TestNG.runSuitesSequentially(TestNG.java:1256)
at org.testng.TestNG.runSuitesLocally(TestNG.java:1176)
at org.testng.TestNG.runSuites(TestNG.java:1099)
at org.testng.TestNG.run(TestNG.java:1067)
at org.testng.remote.AbstractRemoteTestNG.run(AbstractRemoteTestNG.java:115)
at org.testng.remote.RemoteTestNG.initAndRun(RemoteTestNG.java:293)
at org.testng.remote.RemoteTestNG.main(RemoteTestNG.java:91)
Caused by: com.mysql.cj.exceptions.CJCommunicationsException: Communications link failure

The last packet sent successfully to the server was 0 milliseconds ago. The driver has not received any packets from the server.
at java.base/jdk.internal.reflect.DirectConstructorHandleAccessor.newInstance(DirectConstructorHandleAccessor.java:62)
at java.base/java.lang.reflect.Constructor.newInstanceWithCaller(Constructor.java:502)
at java.base/java.lang.reflect.Constructor.newInstance(Constructor.java:486)
at com.mysql.cj.exceptions.ExceptionFactory.createException(ExceptionFactory.java:52)
at com.mysql.cj.exceptions.ExceptionFactory.createException(ExceptionFactory.java:95)
at com.mysql.cj.exceptions.ExceptionFactory.createException(ExceptionFactory.java:140)
at com.mysql.cj.exceptions.ExceptionFactory.createCommunicationsException(ExceptionFactory.java:156)
at com.mysql.cj.protocol.a.NativeSocketConnection.connect(NativeSocketConnection.java:79)
at com.mysql.cj.NativeSession.connect(NativeSession.java:140)
at com.mysql.cj.jdbc.ConnectionImpl.connectOneTryOnly(ConnectionImpl.java:969)
at com.mysql.cj.jdbc.ConnectionImpl.createNewIO(ConnectionImpl.java:833)
... 32 more
Caused by: java.net.ConnectException: Connection refused: connect
at java.base/sun.nio.ch.Net.connect0(Native Method)
at java.base/sun.nio.ch.Net.connect(Net.java:589)
at java.base/sun.nio.ch.Net.connect(Net.java:578)
at java.base/sun.nio.ch.NioSocketImpl.connect(NioSocketImpl.java:583)
at java.base/java.net.SocksSocketImpl.connect(SocksSocketImpl.java:327)
at java.base/java.net.Socket.connect(Socket.java:751)
at com.mysql.cj.protocol.StandardSocketFactory.connect(StandardSocketFactory.java:144)
at com.mysql.cj.protocol.a.NativeSocketConnection.connect(NativeSocketConnection.java:53)
... 35 more
]]>
    </error>
  </testcase> <!-- projectTestTest -->
  <system-out/>
</testsuite> <!-- practice.datadriventesting.SampleUnitTestCaseToCheckProjectInBackEnd -->
